Workbook
Name [開発]運用管理: 'ヒアリングシート(Windows)_old'!#REF!
Name [本番]運用管理: 'ヒアリングシート(Windows)_old'!#REF!
Name _DA: #REF!
Name _DB: #REF!
Name _DC: #REF!
Name _MA: #REF!
Name _MB: #REF!
Name _MC: #REF!
Name aa: [0]!業務終了
Name aaa: 'ヒアリングシート(Windows)_old'!aaa
Name aaaa: 'ヒアリングシート(Windows)_old'!aaaa
Name aaaaaaaaa: 'ヒアリングシート(Windows)_old'!aaaaaaaaa
Name aaaaaaaaaa: 'ヒアリングシート(Windows)_old'!aaaaaaaaaa
Name B: 'ヒアリングシート(Windows)_old'!B
Name bb: 'ヒアリングシート(Windows)_old'!bb
Name CCCCCCCC: 'ヒアリングシート(Windows)_old'!CCCCCCCC
Name CDUPJ: #REF!
Name CDUPY: [1]ＵＴ２進捗管理表!#REF!
Name ＣＤ実績: #REF!
Name ＣＤ予定: #REF!
Name CHOHYO: #REF!
Name D: 'ヒアリングシート(Windows)_old'!D
Name DB: #REF!
Name ｄｄ: #REF!
Name ddd: 'ヒアリングシート(Windows)_old'!ddd
Name ｄｄｄｄｄｄｄ: #REF!
Name EEE: 'ヒアリングシート(Windows)_old'!EEE
Name Endmsg2: 'ヒアリングシート(Windows)_old'!Endmsg2
Name equipment.list: #REF!
Name ｆ: 'ヒアリングシート(Windows)_old'!ｆ
Name G: 'ヒアリングシート(Windows)_old'!G
Name GijutuShonin: #REF!
Name gomi: #REF!
Name H: 'ヒアリングシート(Windows)_old'!H
Name Hyodai: #REF!
Name I: 'ヒアリングシート(Windows)_old'!I
Name J: 'ヒアリングシート(Windows)_old'!J
Name K: 'ヒアリングシート(Windows)_old'!K
Name KAISTP: [1]ＵＴ２進捗管理表!#REF!
Name kubun: #REF!
Name MCLUPJ: #REF!
Name MCLUPY: #REF!
Name Module1.kousu_check: [2]!Module1.kousu_check
Name Module1.SEL_DEL: [3]!Module1.SEL_DEL
Name Module2.Dialogopen: [2]!Module2.Dialogopen
Name Module3.housin2: [4]!Module3.housin2
Name ＮＴサーバ総括表: 'ヒアリングシート(Windows)_old'!ＮＴサーバ総括表
Name PCJUPJ: #REF!
Name PCLUPJ: #REF!
Name PCLUPY: #REF!
Name ＰＤ実績: #REF!
Name ＰＤ予定: #REF!
Name PP見積り: #REF!
Name print: 'ヒアリングシート(Windows)_old'!print
Name print_out: 'ヒアリングシート(Windows)_old'!print_out
Name print_out_NT: 'ヒアリングシート(Windows)_old'!print_out_NT
Name rrr: #REF!
Name save: 'ヒアリングシート(Windows)_old'!save
Name save1: 'ヒアリングシート(Windows)_old'!save1
Name save1_NT: 'ヒアリングシート(Windows)_old'!save1_NT

Sheet ヒアリングシート(Windows)_old
A1: SIチーム用シート(Windows)
B3: ユーザー入力反映欄
B4: 自動反映欄
B6: 項目
B7: サーバ管理名
B8: ランドスケープ | D8: 開発
B9: ランドスケープ | D9: =_xlfn.XLOOKUP(D8,ランドスケープ[名前],ランドスケープ[略称]) -> dev
B10: ランドスケープ | D10: =IF(D8="本番","本番","開発") -> 開発
B11: ロケーション | D11: 外部利用
B12: パブリックIPアドレス必要/不要
B13: インスタンス詳細
B14: 配置先アカウント
B15: 配置先AWSアカウントID | D15: =IF(D14="","※配属先アカウントを選択してください。",_xlfn.XLOOKUP(D14,データ管理シート!$D:$D,データ管理シート!$C:$C)) -> ※配属先アカウントを選択してください。
B16: 配置先AWSアカウント名 | D16: =IF(D14="","※配属先アカウントを選択してください。",_xlfn.XLOOKUP(D14,データ管理シート!$D:$D,データ管理シート!$B:$B)) -> ※配属先アカウントを選択してください。
B17: 配置先VPC | D17: =IF(D14="","※配属先アカウントを選択してください。",_xlfn.XLOOKUP(D14,データ管理シート!$D:$D,データ管理シート!$E:$E)) -> ※配属先アカウントを選択してください。
B18: 配置先VPCID | D18: =IF(D14="","※配属先アカウントを選択してください。",_xlfn.XLOOKUP(D14,データ管理シート!$D:$D,データ管理シート!$F:$F)) -> ※配属先アカウントを選択してください。
B19: 配置先サブネット種類 | D19: プロテクトサブネット
B20: 配置先アベイラビリティゾーン
B21: 配置先サブネット名 | D21: {=_xlfn.IFS(OR(D19="",D20=""),"※配属先サブネット種類、アベイラビリティゾーンを選択してください。",D19="パブリックサブネット","subnet-public-"&RIGHT(D20,2),D19="プロテクトサブネット","subnet-protect-"&RIGHT(D20,2),D19="プライベートサブネット","subnet-private-"&RIGHT(D20,2))} -> ※配属先サブネット種類、アベイラビリティゾーンを選択してください。
B22: 配置先サブネット(subnet-id) | D22: =IF(OR(D19="",D20=""),"※配属先サブネット種類、アベイラビリティゾーンを選択してください。",_xlfn.XLOOKUP(D17&"-"&D21,データ管理シート!$K:$K,データ管理シート!$J:$J)) -> ※配属先サブネット種類、アベイラビリティゾーンを選択してください。
B23: 配置先サブネット(CIDR) | D23: =IF(OR(D19="",D20=""),"※配属先サブネット種類、アベイラビリティゾーンを選択してください。",_xlfn.XLOOKUP(D17&"-"&D21,データ管理シート!$K:$K,データ管理シート!$I:$I)) -> ※配属先サブネット種類、アベイラビリティゾーンを選択してください。
B24: ネットワークインターフェース#1
C25: ネットワークインターフェースID
C26: IPアドレス#1 | D26: =IF(D23="※配属先サブネット種類、アベイラビリティゾーンを選択してください。","",LEFT(D23,11)&"xxx")
C27: パブリックIPアドレス
B28: ネットワークインターフェース#2
C29: ネットワークインターフェースID
C30: IPアドレス#2 | D30: =IF(D23="※配属先サブネット種類、アベイラビリティゾーンを選択してください。","",LEFT(D23,11)&"xxx")
C31: パブリックIPアドレス
B32: DNS#1 | D32: -
B33: DNS#2 | D33: -
B34: NTP | D34: 169.254.169.123
B35: ホスト名定義
C36: システム種類
C37: 環境種類
C38: 会社コード
C39: AWSリージョン
C40: サーバ種類
C41: 連番
B42: インスタンスID
...

Sheet 改版履歴
A1: EC2ヒアリングシート
G3: 改版履歴
G4: 版数 | H4: 日付 | I4: 変更内容 | J4: 担当者
G5: 1.0 | H5: 44496 | I5: 新規作成 | J5: K&K小野
H6: 44505 | I6: 「ユーザ共有シート(Linux)」のF3セルにて式の破損を修正。 | J6: K&K小野
H7: 44508 | I7: 「ヒアリングシート(Windows)」、「ヒアリングシート(Linux)」にて、IFS関数をIF関数に修正。 「ユーザ共有シート(Windows)」、「ユーザ共有シート(Linux)」にて、設定値の条件式を削除して修正。 | J7: K&K小野
H8: 44524 | I8: 「ヒアリングシート(Linux)」にてIAMRole名自動作成修正。 「パラメータシート(Windows/Linux)」にて「オリジナルAMI 名称」自動反映修正。 「データ管理シート」にてAMI情報追加修正 「ヒアリングシート(Windows/Linux)」にて、セル結合を廃止しセル幅を修正。 「ヒアリングシート(Windows/Linux)」にて、プライベートIPアドレス(セカンダリ)の設定項目を追加。 | J8: K&K小野
H9: 44529 | I9: 「ヒアリングシート(Windows/Linux)」にて、プライベートIPアドレス(セカンダリ)の設定項目を1つに削減 「ユーザ共有シート(Windows/Linux)」にて、プライベートIPアドレス(セカンダリ)の設定項目を1つに削減 「パラメータシート(Windows/Linux)」にて、プライベートIPアドレス(セカンダリ)の設定項目を1つに削減 | J9: K&K小野
H10: 44533 | I10: 「データ管理シート」にて、インスタンスタイプM6i情報を追加して更新。 | J10: K&K小野
H11: 44539 | I11: 「ヒアリングシート(Windows/Linux)」にて、AWS運用チーム記載項目を管理コンソール「インスタンスを起動」の項目に合わせて修正 上記ヒアリングシート修正に伴い、「ユーザ共有シート(Windows/Linux)」、「パラメータシート(Windows/Linux)」を修正 | J11: K&K小野
H12: 44546 | I12: 「データ管理シート」にて、インスタンスタイプc6i、r6i情報を追加して更新。 | J12: K&K小野
H13: 44575 | I13: 「ヒアリングシート(Windows/Linux)」にて、Nameタグの命名規則をHostNameタグと同じ命名規則に修正。 | J13: K&K小野
H14: 44578 | I14: 「データ管理シート」にて「OS Windows」、「OS Linux」情報を更新。 | J14: K&K小野
H15: 44580 | I15: 「データ管理シート」にてリージョン情報を追加。 | J15: K&K小野
H16: 44634 | I16: 「データ管理シート」にて、以下アカウント情報を追加。 ・ebr-serv-almighty-prd ([本番][外部]オールマイティ) ・ebr-serv-almighty-dev ([開発][外部]オールマイティ) | J16: K&K小野
H17: 44635 | I17: 「データ管理シート」にて[OS Windows]情報を更新 | J17: K&K小野
... H29: 45581 | I29: 「データ管理シート」に以下アカウント情報を追加。 ・ebr-serv-advanced-dataplatform-dev-internal ・ebr-serv-advanced-dataplatform-prd-internal | J29: K&K小野

Sheet ヒアリングシート(Windows)
A1: ヒアリングシート(Linux)
C3: 【凡例】
C4: 手動で値を入力する項目
C5: プルダウンから値を選択する項目
C6: 自動反映項目
C8: 項目 | L8: サーバ#1
C9: サーバ管理名
C10: リージョン
C11: ランドスケープ
C12: ランドスケープ(略称)
C13: ランドスケープ(表示)
C14: インターネットからの外部接続
C15: CPU
C16: メモリー
C17: OS名
C18: ホスト名定義
D19: システム種類(英数字3桁)
D20: 環境種類
D21: 会社コード
D22: AWSリージョン
D23: サーバ種類
D24: 連番
C25: コストタグ名定義
D26: 会社略称
D27: 部門コード
C28: 通信要件
C29: その他コメント
C30: ディスク１
D31: ドライブ
D32: 容量
D33: ボリュームタイプ
D34: IOPS
D35: スループット
C36: ディスク2
D37: ドライブ
D38: 容量 | L38: 50
D39: ボリュームタイプ | L39: gp3
D40: IOPS | L40: 3000
D41: スループット | L41: 250
C42: ディスク3
...

Sheet ユーザ共有シート(Windows)
C2: 項目 | F2: 設定値
C3: サーバ管理名 | F3: =IF('ヒアリングシート(Windows)'!L9="","-",'ヒアリングシート(Windows)'!L9) -> -
C4: ランドスケープ | F4: =IF('ヒアリングシート(Windows)'!L11="","-",'ヒアリングシート(Windows)'!L11) -> -
C5: ランドスケープ(略称) | F5: =IF(LEFT('ヒアリングシート(Windows)'!L12,1)="※","-",'ヒアリングシート(Windows)'!L12) -> 0
C6: 配置先AWSアカウントID | F6: =IF(LEFT('ヒアリングシート(Windows)'!L108,1)="※","-",'ヒアリングシート(Windows)'!L108) -> 0
C7: 配置先AWSアカウント名 | F7: =IF(LEFT('ヒアリングシート(Windows)'!L109,1)="※","-",'ヒアリングシート(Windows)'!L109) -> 0
C8: 配置先VPC | F8: =IF(LEFT('ヒアリングシート(Windows)'!L110,1)="※","-",'ヒアリングシート(Windows)'!L110) -> 0
C9: 配置先サブネット | F9: =IF(LEFT('ヒアリングシート(Windows)'!L114,1)="※","-",'ヒアリングシート(Windows)'!L114) -> 0
C10: インスタンスタイプ | F10: =IF('ヒアリングシート(Windows)'!L103="","-",'ヒアリングシート(Windows)'!L103) -> -
C11: OS | F11: =IF('ヒアリングシート(Windows)'!L17="","-",'ヒアリングシート(Windows)'!L17) -> -
C12: AMIID | F12: =IF(LEFT('ヒアリングシート(Windows)'!L120,1)="※","-",'ヒアリングシート(Windows)'!L120) -> 0
C13: システム種類 | F13: =IF('ヒアリングシート(Windows)'!L19="","-",'ヒアリングシート(Windows)'!L19) -> -
C14: 環境種類 | F14: =IF(LEFT('ヒアリングシート(Windows)'!L20,1)="※","-",'ヒアリングシート(Windows)'!L20) -> 0
C15: 会社コード | F15: =IF('ヒアリングシート(Windows)'!L21="","-",'ヒアリングシート(Windows)'!L21) -> -
C16: AWSリージョン | F16: =IF('ヒアリングシート(Windows)'!L22="","-",'ヒアリングシート(Windows)'!L22) -> -
C17: サーバ種類 | F17: =IF('ヒアリングシート(Windows)'!L23="","-",'ヒアリングシート(Windows)'!L23) -> -
C18: 連番 | F18: =IF('ヒアリングシート(Windows)'!L24="","-",'ヒアリングシート(Windows)'!L24) -> -
C19: インスタンスID | F19: =IF('ヒアリングシート(Windows)'!L289="","-",'ヒアリングシート(Windows)'!L289) -> -
C20: ホスト名 | F20: =IF(LEFT('ヒアリングシート(Windows)'!L232,1)="※","-",'ヒアリングシート(Windows)'!L232) -> -
C21: Nameタグ | F21: =IF(LEFT('ヒアリングシート(Windows)'!L227,1)="※","-",'ヒアリングシート(Windows)'!L227) -> -
C22: CPU | F22: =IF(LEFT('ヒアリングシート(Windows)'!L123,1)="※","-",'ヒアリングシート(Windows)'!L123) -> 0
C23: メモリー | F23: =IF(LEFT('ヒアリングシート(Windows)'!L124,1)="※","-",'ヒアリングシート(Windows)'!L124) -> 0
C24: Cドライブ(root) | F24: =IF('ヒアリングシート(Windows)'!L31="","-",'ヒアリングシート(Windows)'!L32&"GB"&" ("&'ヒアリングシート(Windows)'!L33&", "&"IOPS:"&'ヒアリングシート(Windows)'!L34&", "&"スループット:"&'ヒアリングシート(Windows)'!L35&"Mbps)") -> -
C25: =IF('ヒアリングシート(Windows)'!L37="",'ヒアリングシート(Windows)'!C36,'ヒアリングシート(Windows)'!L37&"ドライブ"&"("&'ヒアリングシート(Windows)'!L146&")") -> ディスク2 | F25: =IF('ヒアリングシート(Windows)'!L37="","-",'ヒアリングシート(Windows)'!L38&"GB"&" ("&'ヒアリングシート(Windows)'!L39&", "&"IOPS:"&'ヒアリングシート(Windows)'!L40&", "&"スループット:"&'ヒアリングシート(Windows)'!L41&"Mbps)") -> -
C26: =IF('ヒアリングシート(Windows)'!L43="",'ヒアリングシート(Windows)'!C42,'ヒアリングシート(Windows)'!L43&"ドライブ"&"("&'ヒアリングシート(Windows)'!L155&")") -> ディスク3 | F26: =IF('ヒアリングシート(Windows)'!L43="","-",'ヒアリングシート(Windows)'!L44&"GB"&" ("&'ヒアリングシート(Windows)'!L45&", "&"IOPS:"&'ヒアリングシート(Windows)'!L46&", "&"スループット:"&'ヒアリングシート(Windows)'!L47&"Mbps)") -> -
C27: =IF('ヒアリングシート(Windows)'!L49="",'ヒアリングシート(Windows)'!C48,'ヒアリングシート(Windows)'!L49&"ドライブ"&"("&'ヒアリングシート(Windows)'!L164&")") -> ディスク4 | F27: =IF('ヒアリングシート(Windows)'!L49="","-",'ヒアリングシート(Windows)'!L50&"GB"&" ("&'ヒアリングシート(Windows)'!L51&", "&"IOPS:"&'ヒアリングシート(Windows)'!L52&", "&"スループット:"&'ヒアリングシート(Windows)'!L53&"Mbps)") -> -
C28: =IF('ヒアリングシート(Windows)'!L55="",'ヒアリングシート(Windows)'!C54,'ヒアリングシート(Windows)'!L55&"ドライブ"&"("&'ヒアリングシート(Windows)'!L173&")") -> ディスク5 | F28: =IF('ヒアリングシート(Windows)'!L55="","-",'ヒアリングシート(Windows)'!L56&"GB"&" ("&'ヒアリングシート(Windows)'!L57&", "&"IOPS:"&'ヒアリングシート(Windows)'!L58&", "&"スループット:"&'ヒアリングシート(Windows)'!L59&"Mbps)") -> -
C29: =IF('ヒアリングシート(Windows)'!L61="",'ヒアリングシート(Windows)'!C60,'ヒアリングシート(Windows)'!L61&"ドライブ"&"("&'ヒアリングシート(Windows)'!L182&")") -> ディスク6 | F29: =IF('ヒアリングシート(Windows)'!L61="","-",'ヒアリングシート(Windows)'!L62&"GB"&" ("&'ヒアリングシート(Windows)'!L63&", "&"IOPS:"&'ヒアリングシート(Windows)'!L64&", "&"スループット:"&'ヒアリングシート(Windows)'!L65&"Mbps)") -> -
C30: =IF('ヒアリングシート(Windows)'!L67="",'ヒアリングシート(Windows)'!C66,'ヒアリングシート(Windows)'!L67&"ドライブ"&"("&'ヒアリングシート(Windows)'!L191&")") -> ディスク7 | F30: =IF('ヒアリングシート(Windows)'!L67="","-",'ヒアリングシート(Windows)'!L68&"GB"&" ("&'ヒアリングシート(Windows)'!L69&", "&"IOPS:"&'ヒアリングシート(Windows)'!L70&", "&"スループット:"&'ヒアリングシート(Windows)'!L71&"Mbps)") -> -
C31: =IF('ヒアリングシート(Windows)'!L73="",'ヒアリングシート(Windows)'!C72,'ヒアリングシート(Windows)'!L73&"ドライブ"&"("&'ヒアリングシート(Windows)'!L200&")") -> ディスク8 | F31: =IF('ヒアリングシート(Windows)'!L73="","-",'ヒアリングシート(Windows)'!L74&"GB"&" ("&'ヒアリングシート(Windows)'!L75&", "&"IOPS:"&'ヒアリングシート(Windows)'!L76&", "&"スループット:"&'ヒアリングシート(Windows)'!L77&"Mbps)") -> -
C32: =IF('ヒアリングシート(Windows)'!L79="",'ヒアリングシート(Windows)'!C78,'ヒアリングシート(Windows)'!L49&"ドライブ"&"("&'ヒアリングシート(Windows)'!L209&")") -> ディスク9 | F32: =IF('ヒアリングシート(Windows)'!L79="","-",'ヒアリングシート(Windows)'!L80&"GB"&" ("&'ヒアリングシート(Windows)'!L81&", "&"IOPS:"&'ヒアリングシート(Windows)'!L82&", "&"スループット:"&'ヒアリングシート(Windows)'!L83&"Mbps)") -> -
C33: =IF('ヒアリングシート(Windows)'!L85="",'ヒアリングシート(Windows)'!C84,'ヒアリングシート(Windows)'!L85&"ドライブ"&"("&'ヒアリングシート(Windows)'!L218&")") -> ディスク10 | F33: =IF('ヒアリングシート(Windows)'!L85="","-",'ヒアリングシート(Windows)'!L86&"GB"&" ("&'ヒアリングシート(Windows)'!L87&", "&"IOPS:"&'ヒアリングシート(Windows)'!L88&", "&"スループット:"&'ヒアリングシート(Windows)'!L89&"Mbps)") -> -
C34: ディスク暗号化 | F34: =IF('ヒアリングシート(Windows)'!L302="","-",'ヒアリングシート(Windows)'!L302) -> 暗号化済み
C35: ディスク暗号化キー | F35: =IF('ヒアリングシート(Windows)'!L143="","-",'ヒアリングシート(Windows)'!L143) -> aws/ebs
C36: VPC | F36: =IF(LEFT('ヒアリングシート(Windows)'!L110,1)="※","-",'ヒアリングシート(Windows)'!L110) -> 0
C37: サブネット | F37: =IF(LEFT('ヒアリングシート(Windows)'!L114,1)="※","-",'ヒアリングシート(Windows)'!L114) -> 0
C38: サブネット(subnet-id) | F38: =IF(LEFT('ヒアリングシート(Windows)'!L115,1)="※","-",'ヒアリングシート(Windows)'!L115) -> 0
C39: サブネット(CIDR) | F39: =IF(LEFT('ヒアリングシート(Windows)'!L116,1)="※","-",'ヒアリングシート(Windows)'!L116) -> 0
C40: セキュリティグループ#1 | F40: =IF(LEFT('ヒアリングシート(Windows)'!L451,1)="※","-",'ヒアリングシート(Windows)'!L451) -> -
C41: セキュリティグループ#2 | F41: =IF(LEFT('ヒアリングシート(Windows)'!L457,1)="※","-",'ヒアリングシート(Windows)'!L457) -> -
...

Sheet データ共有シート(Windows)
A1: EC2_インスタンス
C3: 項目 | G3: =COLUMN()-6 -> 1 | H3: 備考
C4: インスタンス詳細
D5: サーバ名称 | G5: =IF(LEFT('ヒアリングシート(Windows)'!L227,1)="※","",'ヒアリングシート(Windows)'!L227)
D6: OS
D7: インスタンスID | G7: ='ヒアリングシート(Windows)'!L289 -> 0
D8: インスタンスタイプ | G8: =IF('ヒアリングシート(Windows)'!L103="","",LEFT('ヒアリングシート(Windows)'!L103,FIND(" (",'ヒアリングシート(Windows)'!L103)-1))
D9: VPC名 | G9: =IF(LEFT('ヒアリングシート(Windows)'!L110,1)="※","",'ヒアリングシート(Windows)'!L110) -> 0
D10: VPC ID | G10: =IF(LEFT('ヒアリングシート(Windows)'!L111,1)="※","",'ヒアリングシート(Windows)'!L111) -> 0
D11: サブネット名 | G11: =IF(LEFT('ヒアリングシート(Windows)'!L114,1)="※","",'ヒアリングシート(Windows)'!L114) -> 0
D12: サブネット ID | G12: =IF(LEFT('ヒアリングシート(Windows)'!L115,1)="※","",'ヒアリングシート(Windows)'!L115) -> 0
D13: テナンシー | G13: ='ヒアリングシート(Windows)'!L291 -> Default
D14: アベイラビリティーゾーン | G14: ='ヒアリングシート(Windows)'!L113 -> 0
D15: EBS Optimized | G15: 有効
D16: Termination Protection | G16: ='ヒアリングシート(Windows)'!L290 -> 有効
D17: KeyPair名称 | G17: =IF(LEFT('ヒアリングシート(Windows)'!L286,1)="※","",'ヒアリングシート(Windows)'!L286) -> 0
D18: オリジナルAMI ID | G18: =IF(LEFT('ヒアリングシート(Windows)'!L120,1)="※","",'ヒアリングシート(Windows)'!L120) -> 0
D19: オリジナルAMI 名称 | G19: =IF(LEFT('ヒアリングシート(Windows)'!L119,1)="※","",'ヒアリングシート(Windows)'!L119)
C20: セキュリティ
D21: IAMロール | G21: ='ヒアリングシート(Windows)'!L128 -> ec2role-ssm-managed-access
D22: セキュリティグループ#1 | G22: =IF(LEFT('ヒアリングシート(Windows)'!L451,1)="※","",'ヒアリングシート(Windows)'!L451)
D23: セキュリティグループ#2 | G23: =IF(LEFT('ヒアリングシート(Windows)'!L457,1)="※","",'ヒアリングシート(Windows)'!L457)
C24: ネットワーク
D25: Network Interface | E25: Network Interface ID | G25: ='ヒアリングシート(Windows)'!L293 -> 0
E26: プライベートIPアドレス(プライマリ) | G26: =IF(LEFT('ヒアリングシート(Windows)'!L294,1)="※","",'ヒアリングシート(Windows)'!L294) -> #VALUE!
E27: プライベートIPアドレス(セカンダリ) | G27: =IF(LEFT('ヒアリングシート(Windows)'!L295,1)="","",'ヒアリングシート(Windows)'!L295) -> -
E28: パブリックIPアドレス | G28: =IF('ヒアリングシート(Windows)'!L296="","-",#REF!) -> -
C29: タグ
D30: タグ#1 | E30: Key | G30: =IF(LEFT('ヒアリングシート(Windows)'!L226,1)="※","",'ヒアリングシート(Windows)'!L226)
E31: Value | G31: =IF(LEFT('ヒアリングシート(Windows)'!L227,1)="※","",'ヒアリングシート(Windows)'!L227)
D32: タグ#2 | E32: Key | G32: =IF(LEFT('ヒアリングシート(Windows)'!L231,1)="※","",'ヒアリングシート(Windows)'!L231)
E33: Value | G33: =IF(LEFT('ヒアリングシート(Windows)'!L232,1)="※","",'ヒアリングシート(Windows)'!L232)
D34: タグ#3 | E34: Key | G34: =IF(LEFT('ヒアリングシート(Windows)'!L236,1)="※","",'ヒアリングシート(Windows)'!L236)
E35: Value | G35: =IF(LEFT('ヒアリングシート(Windows)'!L237,1)="※","",'ヒアリングシート(Windows)'!L237)
D36: タグ#4 | E36: Key | G36: =IF(LEFT('ヒアリングシート(Windows)'!L241,1)="※","-",'ヒアリングシート(Windows)'!L241) -> -
E37: Value | G37: =IF(LEFT('ヒアリングシート(Windows)'!L242,1)="※","-",'ヒアリングシート(Windows)'!L242) -> -
D38: タグ#5 | E38: Key | G38: =IF('ヒアリングシート(Windows)'!L246="","-",'ヒアリングシート(Windows)'!L246) -> Backup
E39: Value | G39: =IF('ヒアリングシート(Windows)'!L247="","-",'ヒアリングシート(Windows)'!L247) -> Daily-7day-Retention-JST-0200
D40: タグ#6 | E40: Key | G40: =IF('ヒアリングシート(Windows)'!L251="","-",'ヒアリングシート(Windows)'!L251) -> Cylance
E41: Value | G41: =IF('ヒアリングシート(Windows)'!L252="","-",'ヒアリングシート(Windows)'!L252) -> yes
...

Sheet データ管理シート
A2: 【テーブル新規追加】
A17: 【テーブル列追加】
A28: 【テーブル行追加】
B39: ※テーブルの末尾に値を追加したい場合、最終行直後のセルに値を入力するとテーブルに追加されます。
A42: [アカウント]
B43: [本番外部アカウント]
B44: 用途 | C44: アカウント名 | D44: 表示名
B45: [管理]ネットワーク管理 | C45: ebr-mgmt-network | D45: =アカウント本番外部[[#This Row],[アカウント名]]&" ("&アカウント本番外部[[#This Row],[用途]]&")" -> ebr-mgmt-network ([管理]ネットワーク管理)
B46: [本番][外部]スタンダード | C46: ebr-serv-standard-prd-external | D46: =アカウント本番外部[[#This Row],[アカウント名]]&" ("&アカウント本番外部[[#This Row],[用途]]&")" -> ebr-serv-standard-prd-external ([本番][外部]スタンダード)
B47: [本番][外部]S/4 HANA | C47: ebr-serv-advanced-s4hana-prd-external | D47: =アカウント本番外部[[#This Row],[アカウント名]]&" ("&アカウント本番外部[[#This Row],[用途]]&")" -> ebr-serv-advanced-s4hana-prd-external ([本番][外部]S/4 HANA)
B48: [本番][外部]オールマイティ | C48: ebr-serv-almighty-prd | D48: =アカウント本番外部[[#This Row],[アカウント名]]&" ("&アカウント本番外部[[#This Row],[用途]]&")" -> ebr-serv-almighty-prd ([本番][外部]オールマイティ)
B50: [本番内部アカウント]
B51: 用途 | C51: アカウント名 | D51: 表示名
B52: [本番][内部]運用管理 | C52: ebr-serv-monitoring-prd-internal | D52: =アカウント本番内部[[#This Row],[アカウント名]]&" ("&アカウント本番内部[[#This Row],[用途]]&")" -> ebr-serv-monitoring-prd-internal ([本番][内部]運用管理)
B53: [本番][内部]スタンダード | C53: ebr-serv-standard-prd-internal | D53: =アカウント本番内部[[#This Row],[アカウント名]]&" ("&アカウント本番内部[[#This Row],[用途]]&")" -> ebr-serv-standard-prd-internal ([本番][内部]スタンダード)
B54: [本番][内部]S/4 HANA | C54: ebr-serv-advanced-s4hana-prd-internal | D54: =アカウント本番内部[[#This Row],[アカウント名]]&" ("&アカウント本番内部[[#This Row],[用途]]&")" -> ebr-serv-advanced-s4hana-prd-internal ([本番][内部]S/4 HANA)
B55: [本番][内部]リシテア | C55: ebr-serv-advanced-lysithea-prd-internal | D55: =アカウント本番内部[[#This Row],[アカウント名]]&" ("&アカウント本番内部[[#This Row],[用途]]&")" -> ebr-serv-advanced-lysithea-prd-internal ([本番][内部]リシテア)
B56: [本番][内部]RPA | C56: ebr-serv-advanced-rpa-prd-internal | D56: =アカウント本番内部[[#This Row],[アカウント名]]&" ("&アカウント本番内部[[#This Row],[用途]]&")" -> ebr-serv-advanced-rpa-prd-internal ([本番][内部]RPA)
B57: [本番][内部]GLOVIA | C57: ebr-serv-advanced-glovia-prd-internal | D57: =アカウント本番内部[[#This Row],[アカウント名]]&" ("&アカウント本番内部[[#This Row],[用途]]&")" -> ebr-serv-advanced-glovia-prd-internal ([本番][内部]GLOVIA)
B58: [本番][内部]人事データ | C58: ebr-serv-advanced-hrdatawarehouse-prd-internal | D58: =アカウント本番内部[[#This Row],[アカウント名]]&" ("&アカウント本番内部[[#This Row],[用途]]&")" -> ebr-serv-advanced-hrdatawarehouse-prd-internal ([本番][内部]人事データ)
B59: [本番][内部]DataPlatform | C59: ebr-serv-advanced-dataplatform-prd-internal | D59: =アカウント本番内部[[#This Row],[アカウント名]]&" ("&アカウント本番内部[[#This Row],[用途]]&")" -> ebr-serv-advanced-dataplatform-prd-internal ([本番][内部]DataPlatform)
B61: [開発外部アカウント]
B62: 用途 | C62: アカウント名 | D62: 表示名
B63: [管理]ネットワーク管理 | C63: ebr-mgmt-network | D63: =アカウント開発外部[[#This Row],[アカウント名]]&" ("&アカウント開発外部[[#This Row],[用途]]&")" -> ebr-mgmt-network ([管理]ネットワーク管理)
B64: [開発][外部]スタンダード | C64: ebr-serv-standard-dev-external | D64: =アカウント開発外部[[#This Row],[アカウント名]]&" ("&アカウント開発外部[[#This Row],[用途]]&")" -> ebr-serv-standard-dev-external ([開発][外部]スタンダード)
B65: [開発][外部]S/4 HANA | C65: ebr-serv-advanced-s4hana-dev-external | D65: =アカウント開発外部[[#This Row],[アカウント名]]&" ("&アカウント開発外部[[#This Row],[用途]]&")" -> ebr-serv-advanced-s4hana-dev-external ([開発][外部]S/4 HANA)
B66: [開発][外部]オールマイティ | C66: ebr-serv-almighty-dev | D66: =アカウント開発外部[[#This Row],[アカウント名]]&" ("&アカウント開発外部[[#This Row],[用途]]&")" -> ebr-serv-almighty-dev ([開発][外部]オールマイティ)
B68: [開発内部アカウント]
B69: 用途 | C69: アカウント名 | D69: 表示名
B70: [開発][内部]運用管理 | C70: ebr-serv-monitoring-dev-internal | D70: =アカウント開発内部[[#This Row],[アカウント名]]&" ("&アカウント開発内部[[#This Row],[用途]]&")" -> ebr-serv-monitoring-dev-internal ([開発][内部]運用管理)
B71: [開発][内部]スタンダード | C71: ebr-serv-standard-dev-internal | D71: =アカウント開発内部[[#This Row],[アカウント名]]&" ("&アカウント開発内部[[#This Row],[用途]]&")" -> ebr-serv-standard-dev-internal ([開発][内部]スタンダード)
B72: [開発][内部]S/4 HANA | C72: ebr-serv-advanced-s4hana-dev-internal | D72: =アカウント開発内部[[#This Row],[アカウント名]]&" ("&アカウント開発内部[[#This Row],[用途]]&")" -> ebr-serv-advanced-s4hana-dev-internal ([開発][内部]S/4 HANA)
B73: [開発][内部]リシテア | C73: ebr-serv-advanced-lysithea-dev-internal | D73: =アカウント開発内部[[#This Row],[アカウント名]]&" ("&アカウント開発内部[[#This Row],[用途]]&")" -> ebr-serv-advanced-lysithea-dev-internal ([開発][内部]リシテア)
B74: [開発][内部]RPA | C74: ebr-serv-advanced-rpa-dev-internal | D74: =アカウント開発内部[[#This Row],[アカウント名]]&" ("&アカウント開発内部[[#This Row],[用途]]&")" -> ebr-serv-advanced-rpa-dev-internal ([開発][内部]RPA)
B75: [開発][内部]GLOVIA | C75: ebr-serv-advanced-glovia-dev-internal | D75: =アカウント開発内部[[#This Row],[アカウント名]]&" ("&アカウント開発内部[[#This Row],[用途]]&")" -> ebr-serv-advanced-glovia-dev-internal ([開発][内部]GLOVIA)
B76: [開発][内部]人事データ | C76: ebr-serv-advanced-hrdatawarehouse-dev-internal | D76: =アカウント開発内部[[#This Row],[アカウント名]]&" ("&アカウント開発内部[[#This Row],[用途]]&")" -> ebr-serv-advanced-hrdatawarehouse-dev-internal ([開発][内部]人事データ)
B77: [開発][内部]Fortigate | C77: ebr-serv-advanced-fortigatesc01-dev-internal | D77: =アカウント開発内部[[#This Row],[アカウント名]]&" ("&アカウント開発内部[[#This Row],[用途]]&")" -> ebr-serv-advanced-fortigatesc01-dev-internal ([開発][内部]Fortigate)
B78: [開発][内部]DataPlatform | C78: ebr-serv-advanced-dataplatform-dev-internal | D78: =アカウント開発内部[[#This Row],[アカウント名]]&" ("&アカウント開発内部[[#This Row],[用途]]&")" -> ebr-serv-advanced-dataplatform-dev-internal ([開発][内部]DataPlatform)
B79: [開発][内部]DataPlatform | C79: ebr-serv-advanced-digitaltwin-dev-internal | D79: =アカウント開発内部[[#This Row],[アカウント名]]&" ("&アカウント開発内部[[#This Row],[用途]]&")" -> ebr-serv-advanced-digitaltwin-dev-internal ([開発][内部]DataPlatform)
B80: [開発][内部]DataPlatform | C80: ebr-serv-advanced-digitaltwin-prd-internal | D80: =アカウント開発内部[[#This Row],[アカウント名]]&" ("&アカウント開発内部[[#This Row],[用途]]&")" -> ebr-serv-advanced-digitaltwin-prd-internal ([開発][内部]DataPlatform)
...

Sheet 管理帳登録用
A1: No | B1: Cloud Platform | C1: Network | D1: 3rd Octed | E1: 117 | F1: VPC | G1: region | H1: SubnetName | I1: AvailabilityZone | J1: InstanceID | K1: IP address | L1: LandScape | M1: envタグ | N1: Hostnameタグ | O1: Systemタグ | P1: CostAllocationタグ | Q1: OSタグ | R1: SQLBundleタグ | S1: InstanceType | T1: vCPU | U1: Memory | V1: Disk | W1: OS | Y1: 正管理者 | Z1: 正管理者-連絡先 | AA1: 副管理者 | AB1: 服管理者-連絡先 | AC1: RegisterDate | AD1: Register | AE1: 備考
B2: AWS | C2: 172 | G2: ap-northeast-1
